{
  "timestamp": "2025-06-24T19:34:04.536031",
  "cli_tests": {
    "basic_commands": {
      "help_command": {
        "success": false,
        "output_length": 0,
        "has_usage": false
      },
      "version_command": {
        "success": false,
        "has_version": false
      }
    },
    "data_commands": {
      "data_quality": {
        "success": false,
        "has_output": false
      },
      "data_info": {
        "success": false,
        "has_output": false
      }
    },
    "model_commands": {
      "detector_list": {
        "success": false,
        "has_detectors": false
      }
    },
    "export_commands": {
      "export_formats": {
        "success": false,
        "has_formats": false
      }
    },
    "server_commands": {
      "server_help": {
        "success": false,
        "has_options": false
      }
    }
  },
  "api_tests": {
    "health_endpoints": {
      "/health": {
        "success": false,
        "error": "HTTPConnectionPool(host='localhost', port=8899): Max retries exceeded with url: /health (Caused by NewConnectionError('<urllib3.connection.HTTPConnection object at 0x7fe890e9e690>: Failed to establish a new connection: [Errno 111] Connection refused'))"
      },
      "/health/ready": {
        "success": false,
        "error": "HTTPConnectionPool(host='localhost', port=8899): Max retries exceeded with url: /health/ready (Caused by NewConnectionError('<urllib3.connection.HTTPConnection object at 0x7fe890e9ed20>: Failed to establish a new connection: [Errno 111] Connection refused'))"
      },
      "/health/live": {
        "success": false,
        "error": "HTTPConnectionPool(host='localhost', port=8899): Max retries exceeded with url: /health/live (Caused by NewConnectionError('<urllib3.connection.HTTPConnection object at 0x7fe890e9f440>: Failed to establish a new connection: [Errno 111] Connection refused'))"
      },
      "/": {
        "success": false,
        "error": "HTTPConnectionPool(host='localhost', port=8899): Max retries exceeded with url: / (Caused by NewConnectionError('<urllib3.connection.HTTPConnection object at 0x7fe890e9fb60>: Failed to establish a new connection: [Errno 111] Connection refused'))"
      },
      "/docs": {
        "success": false,
        "error": "HTTPConnectionPool(host='localhost', port=8899): Max retries exceeded with url: /docs (Caused by NewConnectionError('<urllib3.connection.HTTPConnection object at 0x7fe890ed0380>: Failed to establish a new connection: [Errno 111] Connection refused'))"
      }
    },
    "detection_endpoints": {
      "detection_endpoints": {
        "success": false,
        "error": "HTTPConnectionPool(host='localhost', port=8899): Max retries exceeded with url: /api/v1/detect (Caused by NewConnectionError('<urllib3.connection.HTTPConnection object at 0x7fe890e64e00>: Failed to establish a new connection: [Errno 111] Connection refused'))"
      }
    },
    "dataset_endpoints": {
      "dataset_endpoints": {
        "success": false,
        "error": "HTTPConnectionPool(host='localhost', port=8899): Max retries exceeded with url: /api/v1/datasets (Caused by NewConnectionError('<urllib3.connection.HTTPConnection object at 0x7fe890e9fbc0>: Failed to establish a new connection: [Errno 111] Connection refused'))"
      }
    },
    "detector_endpoints": {
      "detector_endpoints": {
        "success": false,
        "error": "HTTPConnectionPool(host='localhost', port=8899): Max retries exceeded with url: /api/v1/detectors (Caused by NewConnectionError('<urllib3.connection.HTTPConnection object at 0x7fe890e9f260>: Failed to establish a new connection: [Errno 111] Connection refused'))"
      }
    }
  },
  "ui_tests": {
    "execution_success": false,
    "output": "\ud83d\ude80 Pynomaly UI Test Suite Runner\n\ud83d\udccd Base URL: http://localhost:8000\n\ud83c\udfad Headless Mode: True\n\ud83d\udcf8 Screenshots: screenshots\n\ud83d\udcca Reports: reports\n\ud83c\udfaf Starting comprehensive UI test suite...\n\ud83d\udd0d Checking server availability...\n\u274c Server not accessible: HTTPConnectionPool(host='localhost', port=8000): Max retries exceeded with url: /health (Caused by NewConnectionError('<urllib3.connection.HTTPConnection object at 0x7f3c4eb730b0>: Failed to establish a new connection: [Errno 111] Connection refused'))\n\ud83d\udca1 Make sure to start the Pynomaly web server first:\n   poetry run uvicorn pynomaly.presentation.api:app --host 127.0.0.1 --port 8000\n",
    "errors": "",
    "test_completion": false,
    "detailed_results": {
      "summary": {
        "total_tests": 7,
        "passed_tests": 3,
        "success_rate": "42.9%",
        "total_duration": "7.61s",
        "screenshots_count": 11
      },
      "detailed_results": [
        {
          "test": "Health Endpoint",
          "status": "PASS",
          "details": "API responding",
          "duration": "0.01s",
          "timestamp": "2025-06-24T18:46:20.856060"
        },
        {
          "test": "Dashboard Load",
          "status": "FAIL",
          "details": "Navigation not visible",
          "duration": "0.53s",
          "timestamp": "2025-06-24T18:46:21.381566"
        },
        {
          "test": "Navigation",
          "status": "PASS",
          "details": "5/5 pages",
          "duration": "3.50s",
          "timestamp": "2025-06-24T18:46:24.877270"
        },
        {
          "test": "Responsive Design",
          "status": "PARTIAL",
          "details": "0/3 viewports",
          "duration": "1.72s",
          "timestamp": "2025-06-24T18:46:26.601557"
        },
        {
          "test": "Mobile Menu",
          "status": "FAIL",
          "details": "Mobile menu button not visible",
          "duration": "0.52s",
          "timestamp": "2025-06-24T18:46:27.125854"
        },
        {
          "test": "Interactive Elements",
          "status": "FAIL",
          "details": "Only 0/3 elements",
          "duration": "0.53s",
          "timestamp": "2025-06-24T18:46:27.651307"
        },
        {
          "test": "Performance",
          "status": "PASS",
          "details": "Load time: 0.51s",
          "duration": "0.51s",
          "timestamp": "2025-06-24T18:46:28.161011"
        }
      ]
    }
  },
  "summary": {
    "total_tests_run": 15,
    "successful_tests": 0,
    "failed_tests": 15,
    "issues_found": [
      "CLI basic_commands.help_command: Failed",
      "CLI basic_commands.version_command: Failed",
      "CLI data_commands.data_quality: Failed",
      "CLI data_commands.data_info: Failed",
      "CLI model_commands.detector_list: Failed",
      "CLI export_commands.export_formats: Failed",
      "CLI server_commands.server_help: Failed",
      "API health_endpoints./health: HTTPConnectionPool(host='localhost', port=8899): Max retries exceeded with url: /health (Caused by NewConnectionError('<urllib3.connection.HTTPConnection object at 0x7fe890e9e690>: Failed to establish a new connection: [Errno 111] Connection refused'))",
      "API health_endpoints./health/ready: HTTPConnectionPool(host='localhost', port=8899): Max retries exceeded with url: /health/ready (Caused by NewConnectionError('<urllib3.connection.HTTPConnection object at 0x7fe890e9ed20>: Failed to establish a new connection: [Errno 111] Connection refused'))",
      "API health_endpoints./health/live: HTTPConnectionPool(host='localhost', port=8899): Max retries exceeded with url: /health/live (Caused by NewConnectionError('<urllib3.connection.HTTPConnection object at 0x7fe890e9f440>: Failed to establish a new connection: [Errno 111] Connection refused'))",
      "API health_endpoints./: HTTPConnectionPool(host='localhost', port=8899): Max retries exceeded with url: / (Caused by NewConnectionError('<urllib3.connection.HTTPConnection object at 0x7fe890e9fb60>: Failed to establish a new connection: [Errno 111] Connection refused'))",
      "API health_endpoints./docs: HTTPConnectionPool(host='localhost', port=8899): Max retries exceeded with url: /docs (Caused by NewConnectionError('<urllib3.connection.HTTPConnection object at 0x7fe890ed0380>: Failed to establish a new connection: [Errno 111] Connection refused'))",
      "API detection_endpoints.detection_endpoints: HTTPConnectionPool(host='localhost', port=8899): Max retries exceeded with url: /api/v1/detect (Caused by NewConnectionError('<urllib3.connection.HTTPConnection object at 0x7fe890e64e00>: Failed to establish a new connection: [Errno 111] Connection refused'))",
      "API dataset_endpoints.dataset_endpoints: HTTPConnectionPool(host='localhost', port=8899): Max retries exceeded with url: /api/v1/datasets (Caused by NewConnectionError('<urllib3.connection.HTTPConnection object at 0x7fe890e9fbc0>: Failed to establish a new connection: [Errno 111] Connection refused'))",
      "API detector_endpoints.detector_endpoints: HTTPConnectionPool(host='localhost', port=8899): Max retries exceeded with url: /api/v1/detectors (Caused by NewConnectionError('<urllib3.connection.HTTPConnection object at 0x7fe890e9f260>: Failed to establish a new connection: [Errno 111] Connection refused'))",
      "UI testing execution failed"
    ],
    "recommendations": [
      "Review failed test details for specific issues",
      "Check dependency installation and environment setup",
      "Verify server startup and port availability",
      "Validate CLI command registration and imports"
    ]
  }
}