# file: C:\Users\andre\Pynomaly\src\pynomaly\domain\exceptions\__init__.py
# hypothesis_version: 6.135.26

['AdapterError', 'AlertNotFoundError', 'AuthenticationError', 'AuthorizationError', 'AutoMLError', 'CacheError', 'ConfigurationError', 'DataTypeError', 'DataValidationError', 'DatasetError', 'DetectorError', 'DomainError', 'EntityNotFoundError', 'ExplainabilityError', 'FeatureMismatchError', 'FittingError', 'InfrastructureError', 'InvalidDataError', 'InvalidValueError', 'ModelNotFoundError', 'NotFittedError', 'ProcessingError', 'PynamolyError', 'ResultError', 'ThresholdError', 'ValidationError']